2025-04-04T14:43:34.992+0000 [INFO] Dependencies all met for dep_context=non-requeueable deps ti=<TaskInstance: iis_etl.processing.load_dimensions scheduled__2025-04-04T14:32:28.760826+00:00 [queued]>
2025-04-04T14:43:35.001+0000 [INFO] Dependencies all met for dep_context=requeueable deps ti=<TaskInstance: iis_etl.processing.load_dimensions scheduled__2025-04-04T14:32:28.760826+00:00 [queued]>
2025-04-04T14:43:35.002+0000 [INFO] Starting attempt 3 of 4
2025-04-04T14:43:35.009+0000 [INFO] Executing <Task(PythonOperator): processing.load_dimensions> on 2025-04-04 14:32:28.760826+00:00
2025-04-04T14:43:35.013+0000 [INFO] Started process 527 to run task
2025-04-04T14:43:35.016+0000 [INFO] Running: ['airflow', 'tasks', 'run', 'iis_etl', 'processing.load_dimensions', 'scheduled__2025-04-04T14:32:28.760826+00:00', '--job-id', '162', '--raw', '--subdir', 'DAGS_FOLDER/iis_etl.py', '--cfg-path', '/tmp/tmpvy85uia2']
2025-04-04T14:43:35.018+0000 [INFO] Job 162: Subtask processing.load_dimensions
2025-04-04T14:43:35.079+0000 [INFO] Running <TaskInstance: iis_etl.processing.load_dimensions scheduled__2025-04-04T14:32:28.760826+00:00 [running]> on host 6adf0d434abe
2025-04-04T14:43:35.309+0000 [INFO] Exporting env vars: AIRFLOW_CTX_DAG_OWNER='airflow' AIRFLOW_CTX_DAG_ID='iis_etl' AIRFLOW_CTX_TASK_ID='processing.load_dimensions' AIRFLOW_CTX_EXECUTION_DATE='2025-04-04T14:32:28.760826+00:00' AIRFLOW_CTX_TRY_NUMBER='3' AIRFLOW_CTX_DAG_RUN_ID='scheduled__2025-04-04T14:32:28.760826+00:00'
2025-04-04T14:43:35.460+0000 [INFO] Using connection ID 'postgres_iis' for task execution.
2025-04-04T14:43:35.551+0000 [ERROR] Task failed with exception
Traceback (most recent call last):
  File "/home/airflow/.local/lib/python3.7/site-packages/airflow/operators/python.py", line 181, in execute
    return_value = self.execute_callable()
  File "/home/airflow/.local/lib/python3.7/site-packages/airflow/operators/python.py", line 198, in execute_callable
    return self.python_callable(*self.op_args, **self.op_kwargs)
  File "/opt/airflow/dags/iis_etl.py", line 256, in load_dimensions
    client_df = df[['c-ip', 'cs(User-Agent)', 'cs(Cookie)', 'cs(Referer)']].drop_duplicates(subset=['c-ip'])
  File "/home/airflow/.local/lib/python3.7/site-packages/pandas/core/frame.py", line 3464, in __getitem__
    indexer = self.loc._get_listlike_indexer(key, axis=1)[1]
  File "/home/airflow/.local/lib/python3.7/site-packages/pandas/core/indexing.py", line 1314, in _get_listlike_indexer
    self._validate_read_indexer(keyarr, indexer, axis)
  File "/home/airflow/.local/lib/python3.7/site-packages/pandas/core/indexing.py", line 1377, in _validate_read_indexer
    raise KeyError(f"{not_found} not in index")
KeyError: "['cs(Cookie)', 'cs(Referer)'] not in index"
2025-04-04T14:43:35.559+0000 [INFO] Marking task as UP_FOR_RETRY. dag_id=iis_etl, task_id=processing.load_dimensions, execution_date=20250404T143228, start_date=20250404T144334, end_date=20250404T144335
2025-04-04T14:43:35.567+0000 [ERROR] Failed to execute job 162 for task processing.load_dimensions ("['cs(Cookie)', 'cs(Referer)'] not in index"; 527)
2025-04-04T14:43:35.610+0000 [INFO] Task exited with return code 1
2025-04-04T14:43:35.635+0000 [INFO] 0 downstream tasks scheduled from follow-on schedule check
