2025-04-04T19:21:52.514+0000 [INFO] Dependencies all met for dep_context=non-requeueable deps ti=<TaskInstance: iis_etl.processing.load_dimensions manual__2025-04-04T19:21:41.704608+00:00 [queued]>
2025-04-04T19:21:52.524+0000 [INFO] Dependencies all met for dep_context=requeueable deps ti=<TaskInstance: iis_etl.processing.load_dimensions manual__2025-04-04T19:21:41.704608+00:00 [queued]>
2025-04-04T19:21:52.526+0000 [INFO] Starting attempt 1 of 4
2025-04-04T19:21:52.535+0000 [INFO] Executing <Task(PythonOperator): processing.load_dimensions> on 2025-04-04 19:21:41.704608+00:00
2025-04-04T19:21:52.539+0000 [INFO] Started process 78 to run task
2025-04-04T19:21:52.542+0000 [INFO] Running: ['airflow', 'tasks', 'run', 'iis_etl', 'processing.load_dimensions', 'manual__2025-04-04T19:21:41.704608+00:00', '--job-id', '13', '--raw', '--subdir', 'DAGS_FOLDER/iis_etl.py', '--cfg-path', '/tmp/tmpvft53ilw']
2025-04-04T19:21:52.544+0000 [INFO] Job 13: Subtask processing.load_dimensions
2025-04-04T19:21:52.577+0000 [INFO] Running <TaskInstance: iis_etl.processing.load_dimensions manual__2025-04-04T19:21:41.704608+00:00 [running]> on host 26473b8dea6a
2025-04-04T19:21:52.793+0000 [INFO] Exporting env vars: AIRFLOW_CTX_DAG_OWNER='airflow' AIRFLOW_CTX_DAG_ID='iis_etl' AIRFLOW_CTX_TASK_ID='processing.load_dimensions' AIRFLOW_CTX_EXECUTION_DATE='2025-04-04T19:21:41.704608+00:00' AIRFLOW_CTX_TRY_NUMBER='1' AIRFLOW_CTX_DAG_RUN_ID='manual__2025-04-04T19:21:41.704608+00:00'
2025-04-04T19:21:52.889+0000 [INFO] Using connection ID 'postgres_iis' for task execution.
2025-04-04T19:21:54.078+0000 [WARNING] Geolocation failed for IP 131.111.37.76: HTTP Error 429: Too Many Requests
2025-04-04T19:21:54.121+0000 [WARNING] Geolocation failed for IP 86.153.189.0: HTTP Error 429: Too Many Requests
2025-04-04T19:21:54.187+0000 [WARNING] Geolocation failed for IP 131.111.37.93: HTTP Error 429: Too Many Requests
2025-04-04T19:21:54.234+0000 [WARNING] Geolocation failed for IP 213.120.115.56: HTTP Error 429: Too Many Requests
2025-04-04T19:21:54.278+0000 [WARNING] Geolocation failed for IP 134.36.36.106: HTTP Error 429: Too Many Requests
2025-04-04T19:21:54.323+0000 [WARNING] Geolocation failed for IP 134.36.36.98: HTTP Error 429: Too Many Requests
2025-04-04T19:21:54.351+0000 [ERROR] Dimension loading failed: (psycopg2.errors.UndefinedColumn) column "country" of relation "dim_clients" does not exist
LINE 4:                     country, state, city, zip_code
                            ^

[SQL: 
                INSERT INTO dim_clients (
                    ip_address, user_agent, browser, os, device_type,
                    country, state, city, zip_code
                )
                SELECT 
                    ip_address, user_agent, browser, os, device_type,
                    country, state, city, zip_code
                FROM temp_clients
                ON CONFLICT (ip_address) DO UPDATE SET
                    user_agent = EXCLUDED.user_agent,
                    browser = EXCLUDED.browser,
                    os = EXCLUDED.os,
                    device_type = EXCLUDED.device_type,
                    country = EXCLUDED.country,
                    state = EXCLUDED.state,
                    city = EXCLUDED.city,
                    zip_code = EXCLUDED.zip_code
            ]
(Background on this error at: https://sqlalche.me/e/14/f405)
Traceback (most recent call last):
  File "/home/airflow/.local/lib/python3.7/site-packages/sqlalchemy/engine/base.py", line 1901, in _execute_context
    cursor, statement, parameters, context
  File "/home/airflow/.local/lib/python3.7/site-packages/sqlalchemy/engine/default.py", line 736, in do_execute
    cursor.execute(statement, parameters)
psycopg2.errors.UndefinedColumn: column "country" of relation "dim_clients" does not exist
LINE 4:                     country, state, city, zip_code
                            ^


The above exception was the direct cause of the following exception:

Traceback (most recent call last):
  File "/opt/airflow/dags/iis_etl.py", line 358, in load_dimensions
    """)
  File "/home/airflow/.local/lib/python3.7/site-packages/sqlalchemy/engine/base.py", line 1370, in execute
    future=False,
  File "/home/airflow/.local/lib/python3.7/site-packages/sqlalchemy/engine/base.py", line 1676, in _exec_driver_sql
    distilled_parameters,
  File "/home/airflow/.local/lib/python3.7/site-packages/sqlalchemy/engine/base.py", line 1944, in _execute_context
    e, statement, parameters, cursor, context
  File "/home/airflow/.local/lib/python3.7/site-packages/sqlalchemy/engine/base.py", line 2125, in _handle_dbapi_exception
    sqlalchemy_exception, with_traceback=exc_info[2], from_=e
  File "/home/airflow/.local/lib/python3.7/site-packages/sqlalchemy/util/compat.py", line 211, in raise_
    raise exception
  File "/home/airflow/.local/lib/python3.7/site-packages/sqlalchemy/engine/base.py", line 1901, in _execute_context
    cursor, statement, parameters, context
  File "/home/airflow/.local/lib/python3.7/site-packages/sqlalchemy/engine/default.py", line 736, in do_execute
    cursor.execute(statement, parameters)
sqlalchemy.exc.ProgrammingError: (psycopg2.errors.UndefinedColumn) column "country" of relation "dim_clients" does not exist
LINE 4:                     country, state, city, zip_code
                            ^

[SQL: 
                INSERT INTO dim_clients (
                    ip_address, user_agent, browser, os, device_type,
                    country, state, city, zip_code
                )
                SELECT 
                    ip_address, user_agent, browser, os, device_type,
                    country, state, city, zip_code
                FROM temp_clients
                ON CONFLICT (ip_address) DO UPDATE SET
                    user_agent = EXCLUDED.user_agent,
                    browser = EXCLUDED.browser,
                    os = EXCLUDED.os,
                    device_type = EXCLUDED.device_type,
                    country = EXCLUDED.country,
                    state = EXCLUDED.state,
                    city = EXCLUDED.city,
                    zip_code = EXCLUDED.zip_code
            ]
(Background on this error at: https://sqlalche.me/e/14/f405)
2025-04-04T19:21:54.361+0000 [ERROR] Task failed with exception
Traceback (most recent call last):
  File "/home/airflow/.local/lib/python3.7/site-packages/sqlalchemy/engine/base.py", line 1901, in _execute_context
    cursor, statement, parameters, context
  File "/home/airflow/.local/lib/python3.7/site-packages/sqlalchemy/engine/default.py", line 736, in do_execute
    cursor.execute(statement, parameters)
psycopg2.errors.UndefinedColumn: column "country" of relation "dim_clients" does not exist
LINE 4:                     country, state, city, zip_code
                            ^


The above exception was the direct cause of the following exception:

Traceback (most recent call last):
  File "/home/airflow/.local/lib/python3.7/site-packages/airflow/operators/python.py", line 181, in execute
    return_value = self.execute_callable()
  File "/home/airflow/.local/lib/python3.7/site-packages/airflow/operators/python.py", line 198, in execute_callable
    return self.python_callable(*self.op_args, **self.op_kwargs)
  File "/opt/airflow/dags/iis_etl.py", line 358, in load_dimensions
    """)
  File "/home/airflow/.local/lib/python3.7/site-packages/sqlalchemy/engine/base.py", line 1370, in execute
    future=False,
  File "/home/airflow/.local/lib/python3.7/site-packages/sqlalchemy/engine/base.py", line 1676, in _exec_driver_sql
    distilled_parameters,
  File "/home/airflow/.local/lib/python3.7/site-packages/sqlalchemy/engine/base.py", line 1944, in _execute_context
    e, statement, parameters, cursor, context
  File "/home/airflow/.local/lib/python3.7/site-packages/sqlalchemy/engine/base.py", line 2125, in _handle_dbapi_exception
    sqlalchemy_exception, with_traceback=exc_info[2], from_=e
  File "/home/airflow/.local/lib/python3.7/site-packages/sqlalchemy/util/compat.py", line 211, in raise_
    raise exception
  File "/home/airflow/.local/lib/python3.7/site-packages/sqlalchemy/engine/base.py", line 1901, in _execute_context
    cursor, statement, parameters, context
  File "/home/airflow/.local/lib/python3.7/site-packages/sqlalchemy/engine/default.py", line 736, in do_execute
    cursor.execute(statement, parameters)
sqlalchemy.exc.ProgrammingError: (psycopg2.errors.UndefinedColumn) column "country" of relation "dim_clients" does not exist
LINE 4:                     country, state, city, zip_code
                            ^

[SQL: 
                INSERT INTO dim_clients (
                    ip_address, user_agent, browser, os, device_type,
                    country, state, city, zip_code
                )
                SELECT 
                    ip_address, user_agent, browser, os, device_type,
                    country, state, city, zip_code
                FROM temp_clients
                ON CONFLICT (ip_address) DO UPDATE SET
                    user_agent = EXCLUDED.user_agent,
                    browser = EXCLUDED.browser,
                    os = EXCLUDED.os,
                    device_type = EXCLUDED.device_type,
                    country = EXCLUDED.country,
                    state = EXCLUDED.state,
                    city = EXCLUDED.city,
                    zip_code = EXCLUDED.zip_code
            ]
(Background on this error at: https://sqlalche.me/e/14/f405)
2025-04-04T19:21:54.374+0000 [INFO] Marking task as UP_FOR_RETRY. dag_id=iis_etl, task_id=processing.load_dimensions, execution_date=20250404T192141, start_date=20250404T192152, end_date=20250404T192154
2025-04-04T19:21:54.387+0000 [ERROR] Failed to execute job 13 for task processing.load_dimensions ((psycopg2.errors.UndefinedColumn) column "country" of relation "dim_clients" does not exist
LINE 4:                     country, state, city, zip_code
                            ^

[SQL: 
                INSERT INTO dim_clients (
                    ip_address, user_agent, browser, os, device_type,
                    country, state, city, zip_code
                )
                SELECT 
                    ip_address, user_agent, browser, os, device_type,
                    country, state, city, zip_code
                FROM temp_clients
                ON CONFLICT (ip_address) DO UPDATE SET
                    user_agent = EXCLUDED.user_agent,
                    browser = EXCLUDED.browser,
                    os = EXCLUDED.os,
                    device_type = EXCLUDED.device_type,
                    country = EXCLUDED.country,
                    state = EXCLUDED.state,
                    city = EXCLUDED.city,
                    zip_code = EXCLUDED.zip_code
            ]
(Background on this error at: https://sqlalche.me/e/14/f405); 78)
2025-04-04T19:21:54.424+0000 [INFO] Task exited with return code 1
2025-04-04T19:21:54.467+0000 [INFO] 0 downstream tasks scheduled from follow-on schedule check
