2025-04-04T18:51:07.163+0000 [INFO] Dependencies all met for dep_context=non-requeueable deps ti=<TaskInstance: iis_etl.processing.load_dimensions scheduled__2025-04-04T18:49:30.333227+00:00 [queued]>
2025-04-04T18:51:07.176+0000 [INFO] Dependencies all met for dep_context=requeueable deps ti=<TaskInstance: iis_etl.processing.load_dimensions scheduled__2025-04-04T18:49:30.333227+00:00 [queued]>
2025-04-04T18:51:07.178+0000 [INFO] Starting attempt 1 of 4
2025-04-04T18:51:07.189+0000 [INFO] Executing <Task(PythonOperator): processing.load_dimensions> on 2025-04-04 18:49:30.333227+00:00
2025-04-04T18:51:07.193+0000 [INFO] Started process 78 to run task
2025-04-04T18:51:07.196+0000 [INFO] Running: ['airflow', 'tasks', 'run', 'iis_etl', 'processing.load_dimensions', 'scheduled__2025-04-04T18:49:30.333227+00:00', '--job-id', '13', '--raw', '--subdir', 'DAGS_FOLDER/iis_etl.py', '--cfg-path', '/tmp/tmpuywj85w0']
2025-04-04T18:51:07.198+0000 [INFO] Job 13: Subtask processing.load_dimensions
2025-04-04T18:51:07.230+0000 [INFO] Running <TaskInstance: iis_etl.processing.load_dimensions scheduled__2025-04-04T18:49:30.333227+00:00 [running]> on host 4c8210097a4d
2025-04-04T18:51:07.443+0000 [INFO] Exporting env vars: AIRFLOW_CTX_DAG_OWNER='airflow' AIRFLOW_CTX_DAG_ID='iis_etl' AIRFLOW_CTX_TASK_ID='processing.load_dimensions' AIRFLOW_CTX_EXECUTION_DATE='2025-04-04T18:49:30.333227+00:00' AIRFLOW_CTX_TRY_NUMBER='1' AIRFLOW_CTX_DAG_RUN_ID='scheduled__2025-04-04T18:49:30.333227+00:00'
2025-04-04T18:51:07.530+0000 [INFO] Using connection ID 'postgres_iis' for task execution.
2025-04-04T18:51:07.667+0000 [ERROR] Dimension loading failed: (psycopg2.errors.InvalidColumnReference) there is no unique or exclusion constraint matching the ON CONFLICT specification

[SQL: 
                INSERT INTO dim_time (timestamp, hour, time_period, date, month, quarter, year)
                SELECT timestamp, hour, time_period, date, month, quarter, year
                FROM temp_time
                ON CONFLICT (timestamp) DO NOTHING
            ]
(Background on this error at: https://sqlalche.me/e/14/f405)
Traceback (most recent call last):
  File "/home/airflow/.local/lib/python3.7/site-packages/sqlalchemy/engine/base.py", line 1901, in _execute_context
    cursor, statement, parameters, context
  File "/home/airflow/.local/lib/python3.7/site-packages/sqlalchemy/engine/default.py", line 736, in do_execute
    cursor.execute(statement, parameters)
psycopg2.errors.InvalidColumnReference: there is no unique or exclusion constraint matching the ON CONFLICT specification


The above exception was the direct cause of the following exception:

Traceback (most recent call last):
  File "/opt/airflow/dags/iis_etl.py", line 383, in load_dimensions
    """)
  File "/home/airflow/.local/lib/python3.7/site-packages/sqlalchemy/engine/base.py", line 1370, in execute
    future=False,
  File "/home/airflow/.local/lib/python3.7/site-packages/sqlalchemy/engine/base.py", line 1676, in _exec_driver_sql
    distilled_parameters,
  File "/home/airflow/.local/lib/python3.7/site-packages/sqlalchemy/engine/base.py", line 1944, in _execute_context
    e, statement, parameters, cursor, context
  File "/home/airflow/.local/lib/python3.7/site-packages/sqlalchemy/engine/base.py", line 2125, in _handle_dbapi_exception
    sqlalchemy_exception, with_traceback=exc_info[2], from_=e
  File "/home/airflow/.local/lib/python3.7/site-packages/sqlalchemy/util/compat.py", line 211, in raise_
    raise exception
  File "/home/airflow/.local/lib/python3.7/site-packages/sqlalchemy/engine/base.py", line 1901, in _execute_context
    cursor, statement, parameters, context
  File "/home/airflow/.local/lib/python3.7/site-packages/sqlalchemy/engine/default.py", line 736, in do_execute
    cursor.execute(statement, parameters)
sqlalchemy.exc.ProgrammingError: (psycopg2.errors.InvalidColumnReference) there is no unique or exclusion constraint matching the ON CONFLICT specification

[SQL: 
                INSERT INTO dim_time (timestamp, hour, time_period, date, month, quarter, year)
                SELECT timestamp, hour, time_period, date, month, quarter, year
                FROM temp_time
                ON CONFLICT (timestamp) DO NOTHING
            ]
(Background on this error at: https://sqlalche.me/e/14/f405)
2025-04-04T18:51:07.669+0000 [ERROR] Task failed with exception
Traceback (most recent call last):
  File "/home/airflow/.local/lib/python3.7/site-packages/sqlalchemy/engine/base.py", line 1901, in _execute_context
    cursor, statement, parameters, context
  File "/home/airflow/.local/lib/python3.7/site-packages/sqlalchemy/engine/default.py", line 736, in do_execute
    cursor.execute(statement, parameters)
psycopg2.errors.InvalidColumnReference: there is no unique or exclusion constraint matching the ON CONFLICT specification


The above exception was the direct cause of the following exception:

Traceback (most recent call last):
  File "/home/airflow/.local/lib/python3.7/site-packages/airflow/operators/python.py", line 181, in execute
    return_value = self.execute_callable()
  File "/home/airflow/.local/lib/python3.7/site-packages/airflow/operators/python.py", line 198, in execute_callable
    return self.python_callable(*self.op_args, **self.op_kwargs)
  File "/opt/airflow/dags/iis_etl.py", line 383, in load_dimensions
    """)
  File "/home/airflow/.local/lib/python3.7/site-packages/sqlalchemy/engine/base.py", line 1370, in execute
    future=False,
  File "/home/airflow/.local/lib/python3.7/site-packages/sqlalchemy/engine/base.py", line 1676, in _exec_driver_sql
    distilled_parameters,
  File "/home/airflow/.local/lib/python3.7/site-packages/sqlalchemy/engine/base.py", line 1944, in _execute_context
    e, statement, parameters, cursor, context
  File "/home/airflow/.local/lib/python3.7/site-packages/sqlalchemy/engine/base.py", line 2125, in _handle_dbapi_exception
    sqlalchemy_exception, with_traceback=exc_info[2], from_=e
  File "/home/airflow/.local/lib/python3.7/site-packages/sqlalchemy/util/compat.py", line 211, in raise_
    raise exception
  File "/home/airflow/.local/lib/python3.7/site-packages/sqlalchemy/engine/base.py", line 1901, in _execute_context
    cursor, statement, parameters, context
  File "/home/airflow/.local/lib/python3.7/site-packages/sqlalchemy/engine/default.py", line 736, in do_execute
    cursor.execute(statement, parameters)
sqlalchemy.exc.ProgrammingError: (psycopg2.errors.InvalidColumnReference) there is no unique or exclusion constraint matching the ON CONFLICT specification

[SQL: 
                INSERT INTO dim_time (timestamp, hour, time_period, date, month, quarter, year)
                SELECT timestamp, hour, time_period, date, month, quarter, year
                FROM temp_time
                ON CONFLICT (timestamp) DO NOTHING
            ]
(Background on this error at: https://sqlalche.me/e/14/f405)
2025-04-04T18:51:07.673+0000 [INFO] Marking task as UP_FOR_RETRY. dag_id=iis_etl, task_id=processing.load_dimensions, execution_date=20250404T184930, start_date=20250404T185107, end_date=20250404T185107
2025-04-04T18:51:07.679+0000 [ERROR] Failed to execute job 13 for task processing.load_dimensions ((psycopg2.errors.InvalidColumnReference) there is no unique or exclusion constraint matching the ON CONFLICT specification

[SQL: 
                INSERT INTO dim_time (timestamp, hour, time_period, date, month, quarter, year)
                SELECT timestamp, hour, time_period, date, month, quarter, year
                FROM temp_time
                ON CONFLICT (timestamp) DO NOTHING
            ]
(Background on this error at: https://sqlalche.me/e/14/f405); 78)
2025-04-04T18:51:07.713+0000 [INFO] Task exited with return code 1
2025-04-04T18:51:07.731+0000 [INFO] 0 downstream tasks scheduled from follow-on schedule check
