2025-04-04T14:45:35.222+0000 [INFO] Dependencies all met for dep_context=non-requeueable deps ti=<TaskInstance: iis_etl.processing.load_dimensions scheduled__2025-04-04T14:34:28.760826+00:00 [queued]>
2025-04-04T14:45:35.231+0000 [INFO] Dependencies all met for dep_context=requeueable deps ti=<TaskInstance: iis_etl.processing.load_dimensions scheduled__2025-04-04T14:34:28.760826+00:00 [queued]>
2025-04-04T14:45:35.231+0000 [INFO] Starting attempt 3 of 4
2025-04-04T14:45:35.242+0000 [INFO] Executing <Task(PythonOperator): processing.load_dimensions> on 2025-04-04 14:34:28.760826+00:00
2025-04-04T14:45:35.246+0000 [INFO] Started process 561 to run task
2025-04-04T14:45:35.250+0000 [INFO] Running: ['airflow', 'tasks', 'run', 'iis_etl', 'processing.load_dimensions', 'scheduled__2025-04-04T14:34:28.760826+00:00', '--job-id', '174', '--raw', '--subdir', 'DAGS_FOLDER/iis_etl.py', '--cfg-path', '/tmp/tmppy7n8_zz']
2025-04-04T14:45:35.252+0000 [INFO] Job 174: Subtask processing.load_dimensions
2025-04-04T14:45:35.300+0000 [INFO] Running <TaskInstance: iis_etl.processing.load_dimensions scheduled__2025-04-04T14:34:28.760826+00:00 [running]> on host 6adf0d434abe
2025-04-04T14:45:35.548+0000 [INFO] Exporting env vars: AIRFLOW_CTX_DAG_OWNER='airflow' AIRFLOW_CTX_DAG_ID='iis_etl' AIRFLOW_CTX_TASK_ID='processing.load_dimensions' AIRFLOW_CTX_EXECUTION_DATE='2025-04-04T14:34:28.760826+00:00' AIRFLOW_CTX_TRY_NUMBER='3' AIRFLOW_CTX_DAG_RUN_ID='scheduled__2025-04-04T14:34:28.760826+00:00'
2025-04-04T14:45:35.599+0000 [INFO] Using connection ID 'postgres_iis' for task execution.
2025-04-04T14:45:35.633+0000 [ERROR] Task failed with exception
Traceback (most recent call last):
  File "/home/airflow/.local/lib/python3.7/site-packages/airflow/operators/python.py", line 181, in execute
    return_value = self.execute_callable()
  File "/home/airflow/.local/lib/python3.7/site-packages/airflow/operators/python.py", line 198, in execute_callable
    return self.python_callable(*self.op_args, **self.op_kwargs)
  File "/opt/airflow/dags/iis_etl.py", line 256, in load_dimensions
    client_df = df[['c-ip', 'cs(User-Agent)', 'cs(Cookie)', 'cs(Referer)']].drop_duplicates(subset=['c-ip'])
  File "/home/airflow/.local/lib/python3.7/site-packages/pandas/core/frame.py", line 3464, in __getitem__
    indexer = self.loc._get_listlike_indexer(key, axis=1)[1]
  File "/home/airflow/.local/lib/python3.7/site-packages/pandas/core/indexing.py", line 1314, in _get_listlike_indexer
    self._validate_read_indexer(keyarr, indexer, axis)
  File "/home/airflow/.local/lib/python3.7/site-packages/pandas/core/indexing.py", line 1377, in _validate_read_indexer
    raise KeyError(f"{not_found} not in index")
KeyError: "['cs(Cookie)', 'cs(Referer)'] not in index"
2025-04-04T14:45:35.640+0000 [INFO] Marking task as UP_FOR_RETRY. dag_id=iis_etl, task_id=processing.load_dimensions, execution_date=20250404T143428, start_date=20250404T144535, end_date=20250404T144535
2025-04-04T14:45:35.646+0000 [ERROR] Failed to execute job 174 for task processing.load_dimensions ("['cs(Cookie)', 'cs(Referer)'] not in index"; 561)
2025-04-04T14:45:35.679+0000 [INFO] Task exited with return code 1
2025-04-04T14:45:35.697+0000 [INFO] 0 downstream tasks scheduled from follow-on schedule check
