2025-04-04T14:35:31.746+0000 [INFO] Dependencies all met for dep_context=non-requeueable deps ti=<TaskInstance: iis_etl.processing.load_dimensions scheduled__2025-04-04T14:34:28.760826+00:00 [queued]>
2025-04-04T14:35:31.755+0000 [INFO] Dependencies all met for dep_context=requeueable deps ti=<TaskInstance: iis_etl.processing.load_dimensions scheduled__2025-04-04T14:34:28.760826+00:00 [queued]>
2025-04-04T14:35:31.756+0000 [INFO] Starting attempt 1 of 4
2025-04-04T14:35:31.768+0000 [INFO] Executing <Task(PythonOperator): processing.load_dimensions> on 2025-04-04 14:34:28.760826+00:00
2025-04-04T14:35:31.783+0000 [INFO] Started process 272 to run task
2025-04-04T14:35:31.826+0000 [INFO] Running: ['airflow', 'tasks', 'run', 'iis_etl', 'processing.load_dimensions', 'scheduled__2025-04-04T14:34:28.760826+00:00', '--job-id', '77', '--raw', '--subdir', 'DAGS_FOLDER/iis_etl.py', '--cfg-path', '/tmp/tmpyd1lrf19']
2025-04-04T14:35:31.829+0000 [INFO] Job 77: Subtask processing.load_dimensions
2025-04-04T14:35:31.956+0000 [INFO] Running <TaskInstance: iis_etl.processing.load_dimensions scheduled__2025-04-04T14:34:28.760826+00:00 [running]> on host 6adf0d434abe
2025-04-04T14:35:33.150+0000 [INFO] Exporting env vars: AIRFLOW_CTX_DAG_OWNER='airflow' AIRFLOW_CTX_DAG_ID='iis_etl' AIRFLOW_CTX_TASK_ID='processing.load_dimensions' AIRFLOW_CTX_EXECUTION_DATE='2025-04-04T14:34:28.760826+00:00' AIRFLOW_CTX_TRY_NUMBER='1' AIRFLOW_CTX_DAG_RUN_ID='scheduled__2025-04-04T14:34:28.760826+00:00'
2025-04-04T14:35:33.177+0000 [ERROR] Task failed with exception
Traceback (most recent call last):
  File "/home/airflow/.local/lib/python3.7/site-packages/airflow/operators/python.py", line 181, in execute
    return_value = self.execute_callable()
  File "/home/airflow/.local/lib/python3.7/site-packages/airflow/operators/python.py", line 198, in execute_callable
    return self.python_callable(*self.op_args, **self.op_kwargs)
  File "/opt/airflow/dags/iis_etl.py", line 232, in load_dimensions
    df = pd.read_json(transformed_data)
  File "/home/airflow/.local/lib/python3.7/site-packages/pandas/util/_decorators.py", line 207, in wrapper
    return func(*args, **kwargs)
  File "/home/airflow/.local/lib/python3.7/site-packages/pandas/util/_decorators.py", line 311, in wrapper
    return func(*args, **kwargs)
  File "/home/airflow/.local/lib/python3.7/site-packages/pandas/io/json/_json.py", line 607, in read_json
    encoding_errors=encoding_errors,
  File "/home/airflow/.local/lib/python3.7/site-packages/pandas/io/json/_json.py", line 675, in __init__
    data = self._get_data_from_filepath(filepath_or_buffer)
  File "/home/airflow/.local/lib/python3.7/site-packages/pandas/io/json/_json.py", line 718, in _get_data_from_filepath
    errors=self.encoding_errors,
  File "/home/airflow/.local/lib/python3.7/site-packages/pandas/io/common.py", line 614, in get_handle
    storage_options=storage_options,
  File "/home/airflow/.local/lib/python3.7/site-packages/pandas/io/common.py", line 396, in _get_filepath_or_buffer
    raise ValueError(msg)
ValueError: Invalid file path or buffer object type: <class 'NoneType'>
2025-04-04T14:35:33.187+0000 [INFO] Marking task as UP_FOR_RETRY. dag_id=iis_etl, task_id=processing.load_dimensions, execution_date=20250404T143428, start_date=20250404T143531, end_date=20250404T143533
2025-04-04T14:35:33.249+0000 [ERROR] Failed to execute job 77 for task processing.load_dimensions (Invalid file path or buffer object type: <class 'NoneType'>; 272)
2025-04-04T14:35:33.323+0000 [INFO] Task exited with return code 1
2025-04-04T14:35:33.386+0000 [INFO] 0 downstream tasks scheduled from follow-on schedule check
