2025-04-04T20:56:44.337+0000 [INFO] Dependencies all met for dep_context=non-requeueable deps ti=<TaskInstance: iis_etl.processing.load_dimensions manual__2025-04-04T20:54:34.363186+00:00 [queued]>
2025-04-04T20:56:44.342+0000 [INFO] Dependencies all met for dep_context=requeueable deps ti=<TaskInstance: iis_etl.processing.load_dimensions manual__2025-04-04T20:54:34.363186+00:00 [queued]>
2025-04-04T20:56:44.342+0000 [INFO] Starting attempt 2 of 4
2025-04-04T20:56:44.349+0000 [INFO] Executing <Task(PythonOperator): processing.load_dimensions> on 2025-04-04 20:54:34.363186+00:00
2025-04-04T20:56:44.353+0000 [INFO] Started process 249 to run task
2025-04-04T20:56:44.356+0000 [INFO] Running: ['airflow', 'tasks', 'run', 'iis_etl', 'processing.load_dimensions', 'manual__2025-04-04T20:54:34.363186+00:00', '--job-id', '70', '--raw', '--subdir', 'DAGS_FOLDER/iis_etl.py', '--cfg-path', '/tmp/tmp8vnixgg6']
2025-04-04T20:56:44.357+0000 [INFO] Job 70: Subtask processing.load_dimensions
2025-04-04T20:56:44.562+0000 [INFO] Running <TaskInstance: iis_etl.processing.load_dimensions manual__2025-04-04T20:54:34.363186+00:00 [running]> on host b8e5693c89ab
2025-04-04T20:56:44.606+0000 [INFO] Exporting env vars: AIRFLOW_CTX_DAG_OWNER='airflow' AIRFLOW_CTX_DAG_ID='iis_etl' AIRFLOW_CTX_TASK_ID='processing.load_dimensions' AIRFLOW_CTX_EXECUTION_DATE='2025-04-04T20:54:34.363186+00:00' AIRFLOW_CTX_TRY_NUMBER='2' AIRFLOW_CTX_DAG_RUN_ID='manual__2025-04-04T20:54:34.363186+00:00'
2025-04-04T20:56:44.664+0000 [INFO] Using connection ID 'postgres_iis' for task execution.
2025-04-04T20:56:44.833+0000 [ERROR] Dimension loading failed: (psycopg2.errors.UndefinedColumn) column "is_api_call" of relation "dim_requests" does not exist
LINE 3: ...          (method, uri_stem, uri_query, username, is_api_cal...
                                                             ^

[SQL: 
                INSERT INTO dim_requests 
                (method, uri_stem, uri_query, username, is_api_call, uri_depth)
                SELECT method, uri_stem, uri_query, username, is_api_call, uri_depth
                FROM temp_requests
                ON CONFLICT (method, uri_stem) DO UPDATE SET
                    uri_query = EXCLUDED.uri_query,
                    username = EXCLUDED.username,
                    is_api_call = EXCLUDED.is_api_call,
                    uri_depth = EXCLUDED.uri_depth
            ]
(Background on this error at: https://sqlalche.me/e/14/f405)
Traceback (most recent call last):
  File "/home/airflow/.local/lib/python3.7/site-packages/sqlalchemy/engine/base.py", line 1901, in _execute_context
    cursor, statement, parameters, context
  File "/home/airflow/.local/lib/python3.7/site-packages/sqlalchemy/engine/default.py", line 736, in do_execute
    cursor.execute(statement, parameters)
psycopg2.errors.UndefinedColumn: column "is_api_call" of relation "dim_requests" does not exist
LINE 3: ...          (method, uri_stem, uri_query, username, is_api_cal...
                                                             ^


The above exception was the direct cause of the following exception:

Traceback (most recent call last):
  File "/opt/airflow/dags/iis_etl.py", line 526, in load_dimensions
    """)
  File "/home/airflow/.local/lib/python3.7/site-packages/sqlalchemy/engine/base.py", line 1370, in execute
    future=False,
  File "/home/airflow/.local/lib/python3.7/site-packages/sqlalchemy/engine/base.py", line 1676, in _exec_driver_sql
    distilled_parameters,
  File "/home/airflow/.local/lib/python3.7/site-packages/sqlalchemy/engine/base.py", line 1944, in _execute_context
    e, statement, parameters, cursor, context
  File "/home/airflow/.local/lib/python3.7/site-packages/sqlalchemy/engine/base.py", line 2125, in _handle_dbapi_exception
    sqlalchemy_exception, with_traceback=exc_info[2], from_=e
  File "/home/airflow/.local/lib/python3.7/site-packages/sqlalchemy/util/compat.py", line 211, in raise_
    raise exception
  File "/home/airflow/.local/lib/python3.7/site-packages/sqlalchemy/engine/base.py", line 1901, in _execute_context
    cursor, statement, parameters, context
  File "/home/airflow/.local/lib/python3.7/site-packages/sqlalchemy/engine/default.py", line 736, in do_execute
    cursor.execute(statement, parameters)
sqlalchemy.exc.ProgrammingError: (psycopg2.errors.UndefinedColumn) column "is_api_call" of relation "dim_requests" does not exist
LINE 3: ...          (method, uri_stem, uri_query, username, is_api_cal...
                                                             ^

[SQL: 
                INSERT INTO dim_requests 
                (method, uri_stem, uri_query, username, is_api_call, uri_depth)
                SELECT method, uri_stem, uri_query, username, is_api_call, uri_depth
                FROM temp_requests
                ON CONFLICT (method, uri_stem) DO UPDATE SET
                    uri_query = EXCLUDED.uri_query,
                    username = EXCLUDED.username,
                    is_api_call = EXCLUDED.is_api_call,
                    uri_depth = EXCLUDED.uri_depth
            ]
(Background on this error at: https://sqlalche.me/e/14/f405)
2025-04-04T20:56:44.835+0000 [ERROR] Task failed with exception
Traceback (most recent call last):
  File "/home/airflow/.local/lib/python3.7/site-packages/sqlalchemy/engine/base.py", line 1901, in _execute_context
    cursor, statement, parameters, context
  File "/home/airflow/.local/lib/python3.7/site-packages/sqlalchemy/engine/default.py", line 736, in do_execute
    cursor.execute(statement, parameters)
psycopg2.errors.UndefinedColumn: column "is_api_call" of relation "dim_requests" does not exist
LINE 3: ...          (method, uri_stem, uri_query, username, is_api_cal...
                                                             ^


The above exception was the direct cause of the following exception:

Traceback (most recent call last):
  File "/home/airflow/.local/lib/python3.7/site-packages/airflow/operators/python.py", line 181, in execute
    return_value = self.execute_callable()
  File "/home/airflow/.local/lib/python3.7/site-packages/airflow/operators/python.py", line 198, in execute_callable
    return self.python_callable(*self.op_args, **self.op_kwargs)
  File "/opt/airflow/dags/iis_etl.py", line 526, in load_dimensions
    """)
  File "/home/airflow/.local/lib/python3.7/site-packages/sqlalchemy/engine/base.py", line 1370, in execute
    future=False,
  File "/home/airflow/.local/lib/python3.7/site-packages/sqlalchemy/engine/base.py", line 1676, in _exec_driver_sql
    distilled_parameters,
  File "/home/airflow/.local/lib/python3.7/site-packages/sqlalchemy/engine/base.py", line 1944, in _execute_context
    e, statement, parameters, cursor, context
  File "/home/airflow/.local/lib/python3.7/site-packages/sqlalchemy/engine/base.py", line 2125, in _handle_dbapi_exception
    sqlalchemy_exception, with_traceback=exc_info[2], from_=e
  File "/home/airflow/.local/lib/python3.7/site-packages/sqlalchemy/util/compat.py", line 211, in raise_
    raise exception
  File "/home/airflow/.local/lib/python3.7/site-packages/sqlalchemy/engine/base.py", line 1901, in _execute_context
    cursor, statement, parameters, context
  File "/home/airflow/.local/lib/python3.7/site-packages/sqlalchemy/engine/default.py", line 736, in do_execute
    cursor.execute(statement, parameters)
sqlalchemy.exc.ProgrammingError: (psycopg2.errors.UndefinedColumn) column "is_api_call" of relation "dim_requests" does not exist
LINE 3: ...          (method, uri_stem, uri_query, username, is_api_cal...
                                                             ^

[SQL: 
                INSERT INTO dim_requests 
                (method, uri_stem, uri_query, username, is_api_call, uri_depth)
                SELECT method, uri_stem, uri_query, username, is_api_call, uri_depth
                FROM temp_requests
                ON CONFLICT (method, uri_stem) DO UPDATE SET
                    uri_query = EXCLUDED.uri_query,
                    username = EXCLUDED.username,
                    is_api_call = EXCLUDED.is_api_call,
                    uri_depth = EXCLUDED.uri_depth
            ]
(Background on this error at: https://sqlalche.me/e/14/f405)
2025-04-04T20:56:44.839+0000 [INFO] Marking task as UP_FOR_RETRY. dag_id=iis_etl, task_id=processing.load_dimensions, execution_date=20250404T205434, start_date=20250404T205644, end_date=20250404T205644
2025-04-04T20:56:44.845+0000 [ERROR] Failed to execute job 70 for task processing.load_dimensions ((psycopg2.errors.UndefinedColumn) column "is_api_call" of relation "dim_requests" does not exist
LINE 3: ...          (method, uri_stem, uri_query, username, is_api_cal...
                                                             ^

[SQL: 
                INSERT INTO dim_requests 
                (method, uri_stem, uri_query, username, is_api_call, uri_depth)
                SELECT method, uri_stem, uri_query, username, is_api_call, uri_depth
                FROM temp_requests
                ON CONFLICT (method, uri_stem) DO UPDATE SET
                    uri_query = EXCLUDED.uri_query,
                    username = EXCLUDED.username,
                    is_api_call = EXCLUDED.is_api_call,
                    uri_depth = EXCLUDED.uri_depth
            ]
(Background on this error at: https://sqlalche.me/e/14/f405); 249)
2025-04-04T20:56:44.880+0000 [INFO] Task exited with return code 1
2025-04-04T20:56:45.013+0000 [INFO] 0 downstream tasks scheduled from follow-on schedule check
