2025-04-04T21:36:25.885+0000 [INFO] Dependencies all met for dep_context=non-requeueable deps ti=<TaskInstance: iis_etl.processing.extract manual__2025-04-04T21:22:32.237586+00:00 [queued]>
2025-04-04T21:36:25.891+0000 [INFO] Dependencies all met for dep_context=requeueable deps ti=<TaskInstance: iis_etl.processing.extract manual__2025-04-04T21:22:32.237586+00:00 [queued]>
2025-04-04T21:36:25.891+0000 [INFO] Starting attempt 3 of 4
2025-04-04T21:36:26.303+0000 [INFO] Executing <Task(PythonOperator): processing.extract> on 2025-04-04 21:22:32.237586+00:00
2025-04-04T21:36:26.322+0000 [INFO] Started process 1569 to run task
2025-04-04T21:36:26.329+0000 [INFO] Running: ['airflow', 'tasks', 'run', 'iis_etl', 'processing.extract', 'manual__2025-04-04T21:22:32.237586+00:00', '--job-id', '510', '--raw', '--subdir', 'DAGS_FOLDER/iis_etl.py', '--cfg-path', '/tmp/tmpr0nntggn']
2025-04-04T21:36:26.332+0000 [INFO] Job 510: Subtask processing.extract
2025-04-04T21:36:26.384+0000 [INFO] Running <TaskInstance: iis_etl.processing.extract manual__2025-04-04T21:22:32.237586+00:00 [running]> on host b8e5693c89ab
2025-04-04T21:36:26.476+0000 [INFO] Exporting env vars: AIRFLOW_CTX_DAG_OWNER='airflow' AIRFLOW_CTX_DAG_ID='iis_etl' AIRFLOW_CTX_TASK_ID='processing.extract' AIRFLOW_CTX_EXECUTION_DATE='2025-04-04T21:22:32.237586+00:00' AIRFLOW_CTX_TRY_NUMBER='3' AIRFLOW_CTX_DAG_RUN_ID='manual__2025-04-04T21:22:32.237586+00:00'
2025-04-04T21:36:26.485+0000 [ERROR] Invalid log file format detected in /opt/airflow/data/raw_logs/u_ex100718.log
2025-04-04T21:36:26.485+0000 [ERROR] Extraction failed: Invalid log file format: /opt/airflow/data/raw_logs/u_ex100718.log
Traceback (most recent call last):
  File "/opt/airflow/dags/iis_etl.py", line 577, in extract
    raise ValueError(f"Invalid log file format: {log_path}")
ValueError: Invalid log file format: /opt/airflow/data/raw_logs/u_ex100718.log
2025-04-04T21:36:26.486+0000 [ERROR] Task failed with exception
Traceback (most recent call last):
  File "/home/airflow/.local/lib/python3.7/site-packages/airflow/operators/python.py", line 181, in execute
    return_value = self.execute_callable()
  File "/home/airflow/.local/lib/python3.7/site-packages/airflow/operators/python.py", line 198, in execute_callable
    return self.python_callable(*self.op_args, **self.op_kwargs)
  File "/opt/airflow/dags/iis_etl.py", line 577, in extract
    raise ValueError(f"Invalid log file format: {log_path}")
ValueError: Invalid log file format: /opt/airflow/data/raw_logs/u_ex100718.log
2025-04-04T21:36:26.492+0000 [INFO] Marking task as UP_FOR_RETRY. dag_id=iis_etl, task_id=processing.extract, execution_date=20250404T212232, start_date=20250404T213625, end_date=20250404T213626
2025-04-04T21:36:26.500+0000 [ERROR] Failed to execute job 510 for task processing.extract (Invalid log file format: /opt/airflow/data/raw_logs/u_ex100718.log; 1569)
2025-04-04T21:36:26.511+0000 [INFO] Task exited with return code 1
2025-04-04T21:36:26.541+0000 [INFO] 0 downstream tasks scheduled from follow-on schedule check
