[2025-04-03T16:32:22.800+0000] {taskinstance.py:1103} INFO - Dependencies all met for dep_context=non-requeueable deps ti=<TaskInstance: iis_etl.processing.transform manual__2025-04-03T16:32:17.916237+00:00 [queued]>
[2025-04-03T16:32:22.810+0000] {taskinstance.py:1103} INFO - Dependencies all met for dep_context=requeueable deps ti=<TaskInstance: iis_etl.processing.transform manual__2025-04-03T16:32:17.916237+00:00 [queued]>
[2025-04-03T16:32:22.812+0000] {taskinstance.py:1308} INFO - Starting attempt 1 of 4
[2025-04-03T16:32:22.823+0000] {taskinstance.py:1327} INFO - Executing <Task(PythonOperator): processing.transform> on 2025-04-03 16:32:17.916237+00:00
[2025-04-03T16:32:22.826+0000] {standard_task_runner.py:57} INFO - Started process 53 to run task
[2025-04-03T16:32:22.829+0000] {standard_task_runner.py:84} INFO - Running: ['airflow', 'tasks', 'run', 'iis_etl', 'processing.transform', 'manual__2025-04-03T16:32:17.916237+00:00', '--job-id', '5', '--raw', '--subdir', 'DAGS_FOLDER/iis_etl.py', '--cfg-path', '/tmp/tmpbd8wdw5y']
[2025-04-03T16:32:22.830+0000] {standard_task_runner.py:85} INFO - Job 5: Subtask processing.transform
[2025-04-03T16:32:22.862+0000] {task_command.py:410} INFO - Running <TaskInstance: iis_etl.processing.transform manual__2025-04-03T16:32:17.916237+00:00 [running]> on host 8c8ff3b60ca4
[2025-04-03T16:32:22.918+0000] {taskinstance.py:1547} INFO - Exporting env vars: AIRFLOW_CTX_DAG_OWNER='airflow' AIRFLOW_CTX_DAG_ID='iis_etl' AIRFLOW_CTX_TASK_ID='processing.transform' AIRFLOW_CTX_EXECUTION_DATE='2025-04-03T16:32:17.916237+00:00' AIRFLOW_CTX_TRY_NUMBER='1' AIRFLOW_CTX_DAG_RUN_ID='manual__2025-04-03T16:32:17.916237+00:00'
[2025-04-03T16:32:22.927+0000] {taskinstance.py:1824} ERROR - Task failed with exception
Traceback (most recent call last):
  File "/home/airflow/.local/lib/python3.7/site-packages/airflow/operators/python.py", line 181, in execute
    return_value = self.execute_callable()
  File "/home/airflow/.local/lib/python3.7/site-packages/airflow/operators/python.py", line 198, in execute_callable
    return self.python_callable(*self.op_args, **self.op_kwargs)
  File "/opt/airflow/dags/iis_etl.py", line 152, in transform
    raise ValueError("No data received from extract task")
ValueError: No data received from extract task
[2025-04-03T16:32:22.937+0000] {taskinstance.py:1350} INFO - Marking task as UP_FOR_RETRY. dag_id=iis_etl, task_id=processing.transform, execution_date=20250403T163217, start_date=20250403T163222, end_date=20250403T163222
[2025-04-03T16:32:22.944+0000] {standard_task_runner.py:109} ERROR - Failed to execute job 5 for task processing.transform (No data received from extract task; 53)
[2025-04-03T16:32:22.969+0000] {local_task_job_runner.py:225} INFO - Task exited with return code 1
[2025-04-03T16:32:22.998+0000] {taskinstance.py:2653} INFO - 0 downstream tasks scheduled from follow-on schedule check
