2025-04-04T15:34:21.494+0000 [INFO] Dependencies all met for dep_context=non-requeueable deps ti=<TaskInstance: iis_etl.processing.load scheduled__2025-04-04T15:13:04.352133+00:00 [queued]>
2025-04-04T15:34:21.527+0000 [INFO] Dependencies all met for dep_context=requeueable deps ti=<TaskInstance: iis_etl.processing.load scheduled__2025-04-04T15:13:04.352133+00:00 [queued]>
2025-04-04T15:34:21.528+0000 [INFO] Starting attempt 4 of 4
2025-04-04T15:34:21.539+0000 [INFO] Executing <Task(PythonOperator): processing.load> on 2025-04-04 15:13:04.352133+00:00
2025-04-04T15:34:21.544+0000 [INFO] Started process 1805 to run task
2025-04-04T15:34:21.550+0000 [INFO] Running: ['airflow', 'tasks', 'run', 'iis_etl', 'processing.load', 'scheduled__2025-04-04T15:13:04.352133+00:00', '--job-id', '588', '--raw', '--subdir', 'DAGS_FOLDER/iis_etl.py', '--cfg-path', '/tmp/tmpxaiv720s']
2025-04-04T15:34:21.552+0000 [INFO] Job 588: Subtask processing.load
2025-04-04T15:34:21.594+0000 [INFO] Running <TaskInstance: iis_etl.processing.load scheduled__2025-04-04T15:13:04.352133+00:00 [running]> on host 6adf0d434abe
2025-04-04T15:34:22.045+0000 [INFO] Exporting env vars: AIRFLOW_CTX_DAG_OWNER='airflow' AIRFLOW_CTX_DAG_ID='iis_etl' AIRFLOW_CTX_TASK_ID='processing.load' AIRFLOW_CTX_EXECUTION_DATE='2025-04-04T15:13:04.352133+00:00' AIRFLOW_CTX_TRY_NUMBER='4' AIRFLOW_CTX_DAG_RUN_ID='scheduled__2025-04-04T15:13:04.352133+00:00'
2025-04-04T15:34:22.127+0000 [INFO] Using connection ID 'postgres_iis' for task execution.
2025-04-04T15:34:22.751+0000 [INFO] Successfully loaded 1069 fact records
2025-04-04T15:34:22.753+0000 [ERROR] Load failed: (psycopg2.errors.UndefinedColumn) column f.time_id does not exist
LINE 6:                 AND f.time_id IS NULL
                            ^
HINT:  Perhaps you meant to reference the column "t.time_id".

[SQL: 
                UPDATE fact_visits f
                SET time_id = t.time_id
                FROM dim_time t
                WHERE f.timestamp = t.timestamp
                AND f.time_id IS NULL
                RETURNING COUNT(*)
            ]
(Background on this error at: https://sqlalche.me/e/14/f405)
Traceback (most recent call last):
  File "/home/airflow/.local/lib/python3.7/site-packages/sqlalchemy/engine/base.py", line 1901, in _execute_context
    cursor, statement, parameters, context
  File "/home/airflow/.local/lib/python3.7/site-packages/sqlalchemy/engine/default.py", line 736, in do_execute
    cursor.execute(statement, parameters)
psycopg2.errors.UndefinedColumn: column f.time_id does not exist
LINE 6:                 AND f.time_id IS NULL
                            ^
HINT:  Perhaps you meant to reference the column "t.time_id".


The above exception was the direct cause of the following exception:

Traceback (most recent call last):
  File "/opt/airflow/dags/iis_etl.py", line 583, in load
    """).scalar()
  File "/home/airflow/.local/lib/python3.7/site-packages/sqlalchemy/engine/base.py", line 1370, in execute
    future=False,
  File "/home/airflow/.local/lib/python3.7/site-packages/sqlalchemy/engine/base.py", line 1676, in _exec_driver_sql
    distilled_parameters,
  File "/home/airflow/.local/lib/python3.7/site-packages/sqlalchemy/engine/base.py", line 1944, in _execute_context
    e, statement, parameters, cursor, context
  File "/home/airflow/.local/lib/python3.7/site-packages/sqlalchemy/engine/base.py", line 2125, in _handle_dbapi_exception
    sqlalchemy_exception, with_traceback=exc_info[2], from_=e
  File "/home/airflow/.local/lib/python3.7/site-packages/sqlalchemy/util/compat.py", line 211, in raise_
    raise exception
  File "/home/airflow/.local/lib/python3.7/site-packages/sqlalchemy/engine/base.py", line 1901, in _execute_context
    cursor, statement, parameters, context
  File "/home/airflow/.local/lib/python3.7/site-packages/sqlalchemy/engine/default.py", line 736, in do_execute
    cursor.execute(statement, parameters)
sqlalchemy.exc.ProgrammingError: (psycopg2.errors.UndefinedColumn) column f.time_id does not exist
LINE 6:                 AND f.time_id IS NULL
                            ^
HINT:  Perhaps you meant to reference the column "t.time_id".

[SQL: 
                UPDATE fact_visits f
                SET time_id = t.time_id
                FROM dim_time t
                WHERE f.timestamp = t.timestamp
                AND f.time_id IS NULL
                RETURNING COUNT(*)
            ]
(Background on this error at: https://sqlalche.me/e/14/f405)
2025-04-04T15:34:22.756+0000 [ERROR] Task failed with exception
Traceback (most recent call last):
  File "/home/airflow/.local/lib/python3.7/site-packages/sqlalchemy/engine/base.py", line 1901, in _execute_context
    cursor, statement, parameters, context
  File "/home/airflow/.local/lib/python3.7/site-packages/sqlalchemy/engine/default.py", line 736, in do_execute
    cursor.execute(statement, parameters)
psycopg2.errors.UndefinedColumn: column f.time_id does not exist
LINE 6:                 AND f.time_id IS NULL
                            ^
HINT:  Perhaps you meant to reference the column "t.time_id".


The above exception was the direct cause of the following exception:

Traceback (most recent call last):
  File "/home/airflow/.local/lib/python3.7/site-packages/airflow/operators/python.py", line 181, in execute
    return_value = self.execute_callable()
  File "/home/airflow/.local/lib/python3.7/site-packages/airflow/operators/python.py", line 198, in execute_callable
    return self.python_callable(*self.op_args, **self.op_kwargs)
  File "/opt/airflow/dags/iis_etl.py", line 583, in load
    """).scalar()
  File "/home/airflow/.local/lib/python3.7/site-packages/sqlalchemy/engine/base.py", line 1370, in execute
    future=False,
  File "/home/airflow/.local/lib/python3.7/site-packages/sqlalchemy/engine/base.py", line 1676, in _exec_driver_sql
    distilled_parameters,
  File "/home/airflow/.local/lib/python3.7/site-packages/sqlalchemy/engine/base.py", line 1944, in _execute_context
    e, statement, parameters, cursor, context
  File "/home/airflow/.local/lib/python3.7/site-packages/sqlalchemy/engine/base.py", line 2125, in _handle_dbapi_exception
    sqlalchemy_exception, with_traceback=exc_info[2], from_=e
  File "/home/airflow/.local/lib/python3.7/site-packages/sqlalchemy/util/compat.py", line 211, in raise_
    raise exception
  File "/home/airflow/.local/lib/python3.7/site-packages/sqlalchemy/engine/base.py", line 1901, in _execute_context
    cursor, statement, parameters, context
  File "/home/airflow/.local/lib/python3.7/site-packages/sqlalchemy/engine/default.py", line 736, in do_execute
    cursor.execute(statement, parameters)
sqlalchemy.exc.ProgrammingError: (psycopg2.errors.UndefinedColumn) column f.time_id does not exist
LINE 6:                 AND f.time_id IS NULL
                            ^
HINT:  Perhaps you meant to reference the column "t.time_id".

[SQL: 
                UPDATE fact_visits f
                SET time_id = t.time_id
                FROM dim_time t
                WHERE f.timestamp = t.timestamp
                AND f.time_id IS NULL
                RETURNING COUNT(*)
            ]
(Background on this error at: https://sqlalche.me/e/14/f405)
2025-04-04T15:34:22.764+0000 [INFO] Marking task as FAILED. dag_id=iis_etl, task_id=processing.load, execution_date=20250404T151304, start_date=20250404T153421, end_date=20250404T153422
2025-04-04T15:34:22.764+0000 [ERROR] Task processing.load failed. Exception: (psycopg2.errors.UndefinedColumn) column f.time_id does not exist
LINE 6:                 AND f.time_id IS NULL
                            ^
HINT:  Perhaps you meant to reference the column "t.time_id".

[SQL: 
                UPDATE fact_visits f
                SET time_id = t.time_id
                FROM dim_time t
                WHERE f.timestamp = t.timestamp
                AND f.time_id IS NULL
                RETURNING COUNT(*)
            ]
(Background on this error at: https://sqlalche.me/e/14/f405)
2025-04-04T15:34:22.773+0000 [ERROR] Failed to execute job 588 for task processing.load ((psycopg2.errors.UndefinedColumn) column f.time_id does not exist
LINE 6:                 AND f.time_id IS NULL
                            ^
HINT:  Perhaps you meant to reference the column "t.time_id".

[SQL: 
                UPDATE fact_visits f
                SET time_id = t.time_id
                FROM dim_time t
                WHERE f.timestamp = t.timestamp
                AND f.time_id IS NULL
                RETURNING COUNT(*)
            ]
(Background on this error at: https://sqlalche.me/e/14/f405); 1805)
2025-04-04T15:34:22.819+0000 [INFO] Task exited with return code 1
2025-04-04T15:34:22.856+0000 [INFO] 1 downstream tasks scheduled from follow-on schedule check
