2025-04-04T18:34:37.240+0000 [INFO] Dependencies all met for dep_context=non-requeueable deps ti=<TaskInstance: iis_etl.processing.load_dimensions manual__2025-04-04T18:23:39.626159+00:00 [queued]>
2025-04-04T18:34:37.250+0000 [INFO] Dependencies all met for dep_context=requeueable deps ti=<TaskInstance: iis_etl.processing.load_dimensions manual__2025-04-04T18:23:39.626159+00:00 [queued]>
2025-04-04T18:34:37.251+0000 [INFO] Starting attempt 2 of 4
2025-04-04T18:34:37.261+0000 [INFO] Executing <Task(PythonOperator): processing.load_dimensions> on 2025-04-04 18:23:39.626159+00:00
2025-04-04T18:34:37.302+0000 [INFO] Started process 90 to run task
2025-04-04T18:34:37.304+0000 [INFO] Running: ['airflow', 'tasks', 'run', 'iis_etl', 'processing.load_dimensions', 'manual__2025-04-04T18:23:39.626159+00:00', '--job-id', '17', '--raw', '--subdir', 'DAGS_FOLDER/iis_etl.py', '--cfg-path', '/tmp/tmpadf9chae']
2025-04-04T18:34:37.310+0000 [INFO] Job 17: Subtask processing.load_dimensions
2025-04-04T18:34:37.414+0000 [INFO] Running <TaskInstance: iis_etl.processing.load_dimensions manual__2025-04-04T18:23:39.626159+00:00 [running]> on host 558dced5c214
2025-04-04T18:34:38.168+0000 [INFO] Exporting env vars: AIRFLOW_CTX_DAG_OWNER='airflow' AIRFLOW_CTX_DAG_ID='iis_etl' AIRFLOW_CTX_TASK_ID='processing.load_dimensions' AIRFLOW_CTX_EXECUTION_DATE='2025-04-04T18:23:39.626159+00:00' AIRFLOW_CTX_TRY_NUMBER='2' AIRFLOW_CTX_DAG_RUN_ID='manual__2025-04-04T18:23:39.626159+00:00'
2025-04-04T18:34:38.221+0000 [INFO] Using connection ID 'postgres_iis' for task execution.
2025-04-04T18:34:38.249+0000 [ERROR] Dimension loading failed: (psycopg2.errors.UniqueViolation) duplicate key value violates unique constraint "dim_clients_ip_address_key"
DETAIL:  Key (ip_address)=(205.178.184.153) already exists.

[SQL: INSERT INTO dim_clients (ip_address, user_agent, browser, os, device_type) VALUES (%(ip_address)s, %(user_agent)s, %(browser)s, %(os)s, %(device_type)s)]
[parameters: ({'ip_address': '205.178.184.153', 'user_agent': 'Mozilla/5.0+(Windows;+U;+Windows+NT+5.1;+en-US;+rv:1.8.1.12)+Gecko/20080201+Firefox/2.0.0.12', 'browser': 'Firefox', 'os': 'Windows', 'device_type': 'Desktop'}, {'ip_address': '91.212.127.100', 'user_agent': 'Mozilla/5.0+(Windows;+U;+Windows+NT+5.0;+en-US;+rv:1.8.1.12)+Gecko/20080201+Firefox/2.0.0.12', 'browser': 'Firefox', 'os': 'Windows', 'device_type': 'Desktop'}, {'ip_address': '204.244.11.121', 'user_agent': 'Plesk', 'browser': 'Other', 'os': 'Other', 'device_type': 'Desktop'})]
(Background on this error at: https://sqlalche.me/e/14/gkpj)
Traceback (most recent call last):
  File "/home/airflow/.local/lib/python3.7/site-packages/sqlalchemy/engine/base.py", line 1881, in _execute_context
    cursor, statement, parameters, context
  File "/home/airflow/.local/lib/python3.7/site-packages/sqlalchemy/dialects/postgresql/psycopg2.py", line 988, in do_executemany
    **kwargs
  File "/home/airflow/.local/lib/python3.7/site-packages/psycopg2/extras.py", line 1299, in execute_values
    cur.execute(b''.join(parts))
psycopg2.errors.UniqueViolation: duplicate key value violates unique constraint "dim_clients_ip_address_key"
DETAIL:  Key (ip_address)=(205.178.184.153) already exists.


The above exception was the direct cause of the following exception:

Traceback (most recent call last):
  File "/opt/airflow/dags/iis_etl.py", line 370, in load_dimensions
    chunksize=1000)
  File "/home/airflow/.local/lib/python3.7/site-packages/pandas/core/generic.py", line 2882, in to_sql
    method=method,
  File "/home/airflow/.local/lib/python3.7/site-packages/pandas/io/sql.py", line 728, in to_sql
    **engine_kwargs,
  File "/home/airflow/.local/lib/python3.7/site-packages/pandas/io/sql.py", line 1770, in to_sql
    **engine_kwargs,
  File "/home/airflow/.local/lib/python3.7/site-packages/pandas/io/sql.py", line 1350, in insert_records
    raise err
  File "/home/airflow/.local/lib/python3.7/site-packages/pandas/io/sql.py", line 1340, in insert_records
    table.insert(chunksize=chunksize, method=method)
  File "/home/airflow/.local/lib/python3.7/site-packages/pandas/io/sql.py", line 967, in insert
    exec_insert(conn, keys, chunk_iter)
  File "/home/airflow/.local/lib/python3.7/site-packages/pandas/io/sql.py", line 882, in _execute_insert
    conn.execute(self.table.insert(), data)
  File "/home/airflow/.local/lib/python3.7/site-packages/sqlalchemy/engine/base.py", line 1380, in execute
    return meth(self, multiparams, params, _EMPTY_EXECUTION_OPTS)
  File "/home/airflow/.local/lib/python3.7/site-packages/sqlalchemy/sql/elements.py", line 335, in _execute_on_connection
    self, multiparams, params, execution_options
  File "/home/airflow/.local/lib/python3.7/site-packages/sqlalchemy/engine/base.py", line 1582, in _execute_clauseelement
    cache_hit=cache_hit,
  File "/home/airflow/.local/lib/python3.7/site-packages/sqlalchemy/engine/base.py", line 1944, in _execute_context
    e, statement, parameters, cursor, context
  File "/home/airflow/.local/lib/python3.7/site-packages/sqlalchemy/engine/base.py", line 2125, in _handle_dbapi_exception
    sqlalchemy_exception, with_traceback=exc_info[2], from_=e
  File "/home/airflow/.local/lib/python3.7/site-packages/sqlalchemy/util/compat.py", line 211, in raise_
    raise exception
  File "/home/airflow/.local/lib/python3.7/site-packages/sqlalchemy/engine/base.py", line 1881, in _execute_context
    cursor, statement, parameters, context
  File "/home/airflow/.local/lib/python3.7/site-packages/sqlalchemy/dialects/postgresql/psycopg2.py", line 988, in do_executemany
    **kwargs
  File "/home/airflow/.local/lib/python3.7/site-packages/psycopg2/extras.py", line 1299, in execute_values
    cur.execute(b''.join(parts))
sqlalchemy.exc.IntegrityError: (psycopg2.errors.UniqueViolation) duplicate key value violates unique constraint "dim_clients_ip_address_key"
DETAIL:  Key (ip_address)=(205.178.184.153) already exists.

[SQL: INSERT INTO dim_clients (ip_address, user_agent, browser, os, device_type) VALUES (%(ip_address)s, %(user_agent)s, %(browser)s, %(os)s, %(device_type)s)]
[parameters: ({'ip_address': '205.178.184.153', 'user_agent': 'Mozilla/5.0+(Windows;+U;+Windows+NT+5.1;+en-US;+rv:1.8.1.12)+Gecko/20080201+Firefox/2.0.0.12', 'browser': 'Firefox', 'os': 'Windows', 'device_type': 'Desktop'}, {'ip_address': '91.212.127.100', 'user_agent': 'Mozilla/5.0+(Windows;+U;+Windows+NT+5.0;+en-US;+rv:1.8.1.12)+Gecko/20080201+Firefox/2.0.0.12', 'browser': 'Firefox', 'os': 'Windows', 'device_type': 'Desktop'}, {'ip_address': '204.244.11.121', 'user_agent': 'Plesk', 'browser': 'Other', 'os': 'Other', 'device_type': 'Desktop'})]
(Background on this error at: https://sqlalche.me/e/14/gkpj)
2025-04-04T18:34:38.259+0000 [ERROR] Task failed with exception
Traceback (most recent call last):
  File "/home/airflow/.local/lib/python3.7/site-packages/sqlalchemy/engine/base.py", line 1881, in _execute_context
    cursor, statement, parameters, context
  File "/home/airflow/.local/lib/python3.7/site-packages/sqlalchemy/dialects/postgresql/psycopg2.py", line 988, in do_executemany
    **kwargs
  File "/home/airflow/.local/lib/python3.7/site-packages/psycopg2/extras.py", line 1299, in execute_values
    cur.execute(b''.join(parts))
psycopg2.errors.UniqueViolation: duplicate key value violates unique constraint "dim_clients_ip_address_key"
DETAIL:  Key (ip_address)=(205.178.184.153) already exists.


The above exception was the direct cause of the following exception:

Traceback (most recent call last):
  File "/home/airflow/.local/lib/python3.7/site-packages/airflow/operators/python.py", line 181, in execute
    return_value = self.execute_callable()
  File "/home/airflow/.local/lib/python3.7/site-packages/airflow/operators/python.py", line 198, in execute_callable
    return self.python_callable(*self.op_args, **self.op_kwargs)
  File "/opt/airflow/dags/iis_etl.py", line 370, in load_dimensions
    chunksize=1000)
  File "/home/airflow/.local/lib/python3.7/site-packages/pandas/core/generic.py", line 2882, in to_sql
    method=method,
  File "/home/airflow/.local/lib/python3.7/site-packages/pandas/io/sql.py", line 728, in to_sql
    **engine_kwargs,
  File "/home/airflow/.local/lib/python3.7/site-packages/pandas/io/sql.py", line 1770, in to_sql
    **engine_kwargs,
  File "/home/airflow/.local/lib/python3.7/site-packages/pandas/io/sql.py", line 1350, in insert_records
    raise err
  File "/home/airflow/.local/lib/python3.7/site-packages/pandas/io/sql.py", line 1340, in insert_records
    table.insert(chunksize=chunksize, method=method)
  File "/home/airflow/.local/lib/python3.7/site-packages/pandas/io/sql.py", line 967, in insert
    exec_insert(conn, keys, chunk_iter)
  File "/home/airflow/.local/lib/python3.7/site-packages/pandas/io/sql.py", line 882, in _execute_insert
    conn.execute(self.table.insert(), data)
  File "/home/airflow/.local/lib/python3.7/site-packages/sqlalchemy/engine/base.py", line 1380, in execute
    return meth(self, multiparams, params, _EMPTY_EXECUTION_OPTS)
  File "/home/airflow/.local/lib/python3.7/site-packages/sqlalchemy/sql/elements.py", line 335, in _execute_on_connection
    self, multiparams, params, execution_options
  File "/home/airflow/.local/lib/python3.7/site-packages/sqlalchemy/engine/base.py", line 1582, in _execute_clauseelement
    cache_hit=cache_hit,
  File "/home/airflow/.local/lib/python3.7/site-packages/sqlalchemy/engine/base.py", line 1944, in _execute_context
    e, statement, parameters, cursor, context
  File "/home/airflow/.local/lib/python3.7/site-packages/sqlalchemy/engine/base.py", line 2125, in _handle_dbapi_exception
    sqlalchemy_exception, with_traceback=exc_info[2], from_=e
  File "/home/airflow/.local/lib/python3.7/site-packages/sqlalchemy/util/compat.py", line 211, in raise_
    raise exception
  File "/home/airflow/.local/lib/python3.7/site-packages/sqlalchemy/engine/base.py", line 1881, in _execute_context
    cursor, statement, parameters, context
  File "/home/airflow/.local/lib/python3.7/site-packages/sqlalchemy/dialects/postgresql/psycopg2.py", line 988, in do_executemany
    **kwargs
  File "/home/airflow/.local/lib/python3.7/site-packages/psycopg2/extras.py", line 1299, in execute_values
    cur.execute(b''.join(parts))
sqlalchemy.exc.IntegrityError: (psycopg2.errors.UniqueViolation) duplicate key value violates unique constraint "dim_clients_ip_address_key"
DETAIL:  Key (ip_address)=(205.178.184.153) already exists.

[SQL: INSERT INTO dim_clients (ip_address, user_agent, browser, os, device_type) VALUES (%(ip_address)s, %(user_agent)s, %(browser)s, %(os)s, %(device_type)s)]
[parameters: ({'ip_address': '205.178.184.153', 'user_agent': 'Mozilla/5.0+(Windows;+U;+Windows+NT+5.1;+en-US;+rv:1.8.1.12)+Gecko/20080201+Firefox/2.0.0.12', 'browser': 'Firefox', 'os': 'Windows', 'device_type': 'Desktop'}, {'ip_address': '91.212.127.100', 'user_agent': 'Mozilla/5.0+(Windows;+U;+Windows+NT+5.0;+en-US;+rv:1.8.1.12)+Gecko/20080201+Firefox/2.0.0.12', 'browser': 'Firefox', 'os': 'Windows', 'device_type': 'Desktop'}, {'ip_address': '204.244.11.121', 'user_agent': 'Plesk', 'browser': 'Other', 'os': 'Other', 'device_type': 'Desktop'})]
(Background on this error at: https://sqlalche.me/e/14/gkpj)
2025-04-04T18:34:38.267+0000 [INFO] Marking task as UP_FOR_RETRY. dag_id=iis_etl, task_id=processing.load_dimensions, execution_date=20250404T182339, start_date=20250404T183437, end_date=20250404T183438
2025-04-04T18:34:38.312+0000 [ERROR] Failed to execute job 17 for task processing.load_dimensions ((psycopg2.errors.UniqueViolation) duplicate key value violates unique constraint "dim_clients_ip_address_key"
DETAIL:  Key (ip_address)=(205.178.184.153) already exists.

[SQL: INSERT INTO dim_clients (ip_address, user_agent, browser, os, device_type) VALUES (%(ip_address)s, %(user_agent)s, %(browser)s, %(os)s, %(device_type)s)]
[parameters: ({'ip_address': '205.178.184.153', 'user_agent': 'Mozilla/5.0+(Windows;+U;+Windows+NT+5.1;+en-US;+rv:1.8.1.12)+Gecko/20080201+Firefox/2.0.0.12', 'browser': 'Firefox', 'os': 'Windows', 'device_type': 'Desktop'}, {'ip_address': '91.212.127.100', 'user_agent': 'Mozilla/5.0+(Windows;+U;+Windows+NT+5.0;+en-US;+rv:1.8.1.12)+Gecko/20080201+Firefox/2.0.0.12', 'browser': 'Firefox', 'os': 'Windows', 'device_type': 'Desktop'}, {'ip_address': '204.244.11.121', 'user_agent': 'Plesk', 'browser': 'Other', 'os': 'Other', 'device_type': 'Desktop'})]
(Background on this error at: https://sqlalche.me/e/14/gkpj); 90)
2025-04-04T18:34:38.367+0000 [INFO] Task exited with return code 1
2025-04-04T18:34:38.444+0000 [INFO] 0 downstream tasks scheduled from follow-on schedule check
