2025-04-04T19:24:17.973+0000 [INFO] Dependencies all met for dep_context=non-requeueable deps ti=<TaskInstance: iis_etl.processing.load_dimensions scheduled__2025-04-04T19:23:12.003875+00:00 [queued]>
2025-04-04T19:24:17.981+0000 [INFO] Dependencies all met for dep_context=requeueable deps ti=<TaskInstance: iis_etl.processing.load_dimensions scheduled__2025-04-04T19:23:12.003875+00:00 [queued]>
2025-04-04T19:24:17.982+0000 [INFO] Starting attempt 1 of 4
2025-04-04T19:24:17.990+0000 [INFO] Executing <Task(PythonOperator): processing.load_dimensions> on 2025-04-04 19:23:12.003875+00:00
2025-04-04T19:24:17.993+0000 [INFO] Started process 132 to run task
2025-04-04T19:24:17.996+0000 [INFO] Running: ['airflow', 'tasks', 'run', 'iis_etl', 'processing.load_dimensions', 'scheduled__2025-04-04T19:23:12.003875+00:00', '--job-id', '31', '--raw', '--subdir', 'DAGS_FOLDER/iis_etl.py', '--cfg-path', '/tmp/tmpm00g4rdr']
2025-04-04T19:24:17.997+0000 [INFO] Job 31: Subtask processing.load_dimensions
2025-04-04T19:24:18.028+0000 [INFO] Running <TaskInstance: iis_etl.processing.load_dimensions scheduled__2025-04-04T19:23:12.003875+00:00 [running]> on host 26473b8dea6a
2025-04-04T19:24:18.246+0000 [INFO] Exporting env vars: AIRFLOW_CTX_DAG_OWNER='airflow' AIRFLOW_CTX_DAG_ID='iis_etl' AIRFLOW_CTX_TASK_ID='processing.load_dimensions' AIRFLOW_CTX_EXECUTION_DATE='2025-04-04T19:23:12.003875+00:00' AIRFLOW_CTX_TRY_NUMBER='1' AIRFLOW_CTX_DAG_RUN_ID='scheduled__2025-04-04T19:23:12.003875+00:00'
2025-04-04T19:24:18.300+0000 [INFO] Using connection ID 'postgres_iis' for task execution.
2025-04-04T19:24:20.461+0000 [ERROR] Dimension loading failed: (psycopg2.errors.UndefinedColumn) column "country" of relation "dim_clients" does not exist
LINE 4:                     country, state, city, zip_code
                            ^

[SQL: 
                INSERT INTO dim_clients (
                    ip_address, user_agent, browser, os, device_type,
                    country, state, city, zip_code
                )
                SELECT 
                    ip_address, user_agent, browser, os, device_type,
                    country, state, city, zip_code
                FROM temp_clients
                ON CONFLICT (ip_address) DO UPDATE SET
                    user_agent = EXCLUDED.user_agent,
                    browser = EXCLUDED.browser,
                    os = EXCLUDED.os,
                    device_type = EXCLUDED.device_type,
                    country = EXCLUDED.country,
                    state = EXCLUDED.state,
                    city = EXCLUDED.city,
                    zip_code = EXCLUDED.zip_code
            ]
(Background on this error at: https://sqlalche.me/e/14/f405)
Traceback (most recent call last):
  File "/home/airflow/.local/lib/python3.7/site-packages/sqlalchemy/engine/base.py", line 1901, in _execute_context
    cursor, statement, parameters, context
  File "/home/airflow/.local/lib/python3.7/site-packages/sqlalchemy/engine/default.py", line 736, in do_execute
    cursor.execute(statement, parameters)
psycopg2.errors.UndefinedColumn: column "country" of relation "dim_clients" does not exist
LINE 4:                     country, state, city, zip_code
                            ^


The above exception was the direct cause of the following exception:

Traceback (most recent call last):
  File "/opt/airflow/dags/iis_etl.py", line 358, in load_dimensions
    """)
  File "/home/airflow/.local/lib/python3.7/site-packages/sqlalchemy/engine/base.py", line 1370, in execute
    future=False,
  File "/home/airflow/.local/lib/python3.7/site-packages/sqlalchemy/engine/base.py", line 1676, in _exec_driver_sql
    distilled_parameters,
  File "/home/airflow/.local/lib/python3.7/site-packages/sqlalchemy/engine/base.py", line 1944, in _execute_context
    e, statement, parameters, cursor, context
  File "/home/airflow/.local/lib/python3.7/site-packages/sqlalchemy/engine/base.py", line 2125, in _handle_dbapi_exception
    sqlalchemy_exception, with_traceback=exc_info[2], from_=e
  File "/home/airflow/.local/lib/python3.7/site-packages/sqlalchemy/util/compat.py", line 211, in raise_
    raise exception
  File "/home/airflow/.local/lib/python3.7/site-packages/sqlalchemy/engine/base.py", line 1901, in _execute_context
    cursor, statement, parameters, context
  File "/home/airflow/.local/lib/python3.7/site-packages/sqlalchemy/engine/default.py", line 736, in do_execute
    cursor.execute(statement, parameters)
sqlalchemy.exc.ProgrammingError: (psycopg2.errors.UndefinedColumn) column "country" of relation "dim_clients" does not exist
LINE 4:                     country, state, city, zip_code
                            ^

[SQL: 
                INSERT INTO dim_clients (
                    ip_address, user_agent, browser, os, device_type,
                    country, state, city, zip_code
                )
                SELECT 
                    ip_address, user_agent, browser, os, device_type,
                    country, state, city, zip_code
                FROM temp_clients
                ON CONFLICT (ip_address) DO UPDATE SET
                    user_agent = EXCLUDED.user_agent,
                    browser = EXCLUDED.browser,
                    os = EXCLUDED.os,
                    device_type = EXCLUDED.device_type,
                    country = EXCLUDED.country,
                    state = EXCLUDED.state,
                    city = EXCLUDED.city,
                    zip_code = EXCLUDED.zip_code
            ]
(Background on this error at: https://sqlalche.me/e/14/f405)
2025-04-04T19:24:20.468+0000 [ERROR] Task failed with exception
Traceback (most recent call last):
  File "/home/airflow/.local/lib/python3.7/site-packages/sqlalchemy/engine/base.py", line 1901, in _execute_context
    cursor, statement, parameters, context
  File "/home/airflow/.local/lib/python3.7/site-packages/sqlalchemy/engine/default.py", line 736, in do_execute
    cursor.execute(statement, parameters)
psycopg2.errors.UndefinedColumn: column "country" of relation "dim_clients" does not exist
LINE 4:                     country, state, city, zip_code
                            ^


The above exception was the direct cause of the following exception:

Traceback (most recent call last):
  File "/home/airflow/.local/lib/python3.7/site-packages/airflow/operators/python.py", line 181, in execute
    return_value = self.execute_callable()
  File "/home/airflow/.local/lib/python3.7/site-packages/airflow/operators/python.py", line 198, in execute_callable
    return self.python_callable(*self.op_args, **self.op_kwargs)
  File "/opt/airflow/dags/iis_etl.py", line 358, in load_dimensions
    """)
  File "/home/airflow/.local/lib/python3.7/site-packages/sqlalchemy/engine/base.py", line 1370, in execute
    future=False,
  File "/home/airflow/.local/lib/python3.7/site-packages/sqlalchemy/engine/base.py", line 1676, in _exec_driver_sql
    distilled_parameters,
  File "/home/airflow/.local/lib/python3.7/site-packages/sqlalchemy/engine/base.py", line 1944, in _execute_context
    e, statement, parameters, cursor, context
  File "/home/airflow/.local/lib/python3.7/site-packages/sqlalchemy/engine/base.py", line 2125, in _handle_dbapi_exception
    sqlalchemy_exception, with_traceback=exc_info[2], from_=e
  File "/home/airflow/.local/lib/python3.7/site-packages/sqlalchemy/util/compat.py", line 211, in raise_
    raise exception
  File "/home/airflow/.local/lib/python3.7/site-packages/sqlalchemy/engine/base.py", line 1901, in _execute_context
    cursor, statement, parameters, context
  File "/home/airflow/.local/lib/python3.7/site-packages/sqlalchemy/engine/default.py", line 736, in do_execute
    cursor.execute(statement, parameters)
sqlalchemy.exc.ProgrammingError: (psycopg2.errors.UndefinedColumn) column "country" of relation "dim_clients" does not exist
LINE 4:                     country, state, city, zip_code
                            ^

[SQL: 
                INSERT INTO dim_clients (
                    ip_address, user_agent, browser, os, device_type,
                    country, state, city, zip_code
                )
                SELECT 
                    ip_address, user_agent, browser, os, device_type,
                    country, state, city, zip_code
                FROM temp_clients
                ON CONFLICT (ip_address) DO UPDATE SET
                    user_agent = EXCLUDED.user_agent,
                    browser = EXCLUDED.browser,
                    os = EXCLUDED.os,
                    device_type = EXCLUDED.device_type,
                    country = EXCLUDED.country,
                    state = EXCLUDED.state,
                    city = EXCLUDED.city,
                    zip_code = EXCLUDED.zip_code
            ]
(Background on this error at: https://sqlalche.me/e/14/f405)
2025-04-04T19:24:20.494+0000 [INFO] Marking task as UP_FOR_RETRY. dag_id=iis_etl, task_id=processing.load_dimensions, execution_date=20250404T192312, start_date=20250404T192417, end_date=20250404T192420
2025-04-04T19:24:20.505+0000 [ERROR] Failed to execute job 31 for task processing.load_dimensions ((psycopg2.errors.UndefinedColumn) column "country" of relation "dim_clients" does not exist
LINE 4:                     country, state, city, zip_code
                            ^

[SQL: 
                INSERT INTO dim_clients (
                    ip_address, user_agent, browser, os, device_type,
                    country, state, city, zip_code
                )
                SELECT 
                    ip_address, user_agent, browser, os, device_type,
                    country, state, city, zip_code
                FROM temp_clients
                ON CONFLICT (ip_address) DO UPDATE SET
                    user_agent = EXCLUDED.user_agent,
                    browser = EXCLUDED.browser,
                    os = EXCLUDED.os,
                    device_type = EXCLUDED.device_type,
                    country = EXCLUDED.country,
                    state = EXCLUDED.state,
                    city = EXCLUDED.city,
                    zip_code = EXCLUDED.zip_code
            ]
(Background on this error at: https://sqlalche.me/e/14/f405); 132)
2025-04-04T19:24:20.519+0000 [INFO] Task exited with return code 1
2025-04-04T19:24:20.544+0000 [INFO] 0 downstream tasks scheduled from follow-on schedule check
